{"error": null, "issues": [{"address": 827, "code": "sses.length;\n            u", "debug": "", "description": "Multiple sends exist in one transaction, try to isolate each external call into its own transaction. As external calls can fail accidentally or deliberately.\nConsecutive calls: \nCall at address: 2480\nCall at address: 2115\nCall at address: 2115\nCall at address: 1791\nCall at address: 1599\nCall at address: 2480\nCall at address: 1599\nCall at address: 2480\nCall at address: 2115\nCall at address: 2115\nCall at address: 1791\nCall at address: 1599\nCall at address: 2480\nCall at address: 1599\n", "filename": "/temp/Grandiose-0.sol", "function": "fallback", "lineno": 98, "title": "Multiple Calls", "type": "Information"}, {"address": 860, "code": ";\n/*\n             ", "debug": "storage_7: 0xffffffffffffffffffffffffffffffffffffffffffffffffffffffffffffffff\ncallvalue: 0x8000000000000000000000000000000000000000000000000020000000000000\nretval_827: 0xffffffffffffffffffffffffffffffffffffffffffffffffffffffffffffffff\nstorage_9: 0x0\ncaller: 0x0\nstorage_0: 0xffffffffffffffffffffffffffffffffffffffff00\ncalldatasize_Grandiose: 0x3\nstorage_0 +\nkeccac_1461501637330902918203684832716283019655932542975_&\n1461501637330902918203684832716283019655932542975_&\ncaller: 0x0\n", "description": "A possible integer overflow exists in the function `fallback`.\nThe addition or multiplication may result in a value higher than the maximum representable integer.", "filename": "/temp/Grandiose-0.sol", "function": "fallback", "lineno": 1, "title": "Integer Overflow ", "type": "Warning"}, {"address": 1261, "code": "er);\n\n        depositAmou", "debug": "callvalue: 0xcacb402a20200a09822135dfffffeff922203dffe9ef89df702387f26fc88c13\nstorage_1 +\nkeccac_1461501637330902918203684832716283019655932542975_&\n1461501637330902918203684832716283019655932542975_&\ncaller: 0xea439ff13bdff5fd84040010000000015ddfc2000c04018f81d8780d90138c40\nstorage_42968895388377710148156740012165625056958882193801299486065383385270288799432: 0xffffffffffffffffffffffffffffffffffffffffffffffffffffffffffffffff\nretval_827: 0xffffffffffffffffffffffffffffffffffffffffffffffffffffffffffffffff\nstorage_9: 0x0\ncaller: 0xffffffffffffffffffffffffffffffffffffffff\nstorage_0: 0x0\ncalldatasize_Grandiose: 0x3\nstorage_0 +\nkeccac_1461501637330902918203684832716283019655932542975_&\n1461501637330902918203684832716283019655932542975_&\ncaller: 0x0\n", "description": "A possible integer overflow exists in the function `fallback`.\nThe addition or multiplication may result in a value higher than the maximum representable integer.", "filename": "/temp/Grandiose-0.sol", "function": "fallback", "lineno": 114, "title": "Integer Overflow ", "type": "Warning"}, {"address": 1280, "code": "alue;\n        last", "debug": "storage_2 +\nkeccac_1461501637330902918203684832716283019655932542975_&\n1461501637330902918203684832716283019655932542975_&\ncaller: 0xffffffffffffffffffffffffffffffffffffffffffffffffffffffffffffffff\ncallvalue: 0x8000000000000000000000000000000000000000000000000020000000000000\nstorage_42968895388377710148156740012165625056958882193801299486065383385270288799432: 0xffffffffffffffffffffffffffffffffffffffffffffffffffffffffffffffff\nretval_827: 0xffffffffffffffffffffffffffffffffffffffffffffffffffffffffffffffff\nstorage_9: 0x0\ncaller: 0xffffffffffffffffffffffffffffffffffffffff\nstorage_0: 0x0\ncalldatasize_Grandiose: 0x3\nstorage_0 +\nkeccac_1461501637330902918203684832716283019655932542975_&\n1461501637330902918203684832716283019655932542975_&\ncaller: 0x0\n", "description": "A possible integer overflow exists in the function `fallback`.\nThe addition or multiplication may result in a value higher than the maximum representable integer.", "filename": "/temp/Grandiose-0.sol", "function": "fallback", "lineno": 116, "title": "Integer Overflow ", "type": "Warning"}, {"address": 1491, "code": "ee\n        uint bonusAmoun", "debug": "storage_2: 0xea439ff13bdff5fd84040010000000015ddfc2000c04018f81d8780d90138c40\ncallvalue: 0xcacb402a20200a09822135dfffffeff922203dffe9ef89df702387f26fc88c13\nstorage_42968895388377710148156740012165625056958882193801299486065383385270288799432: 0xffffffffffffffffffffffffffffffffffffffffffffffffffffffffffffffff\nretval_827: 0xffffffffffffffffffffffffffffffffffffffffffffffffffffffffffffffff\nstorage_9: 0x0\ncaller: 0xffffffffffffffffffffffffffffffffffffffff\nstorage_0: 0x0\ncalldatasize_Grandiose: 0x3\nstorage_0 +\nkeccac_1461501637330902918203684832716283019655932542975_&\n1461501637330902918203684832716283019655932542975_&\ncaller: 0x0\n", "description": "A possible integer overflow exists in the function `fallback`.\nThe addition or multiplication may result in a value higher than the maximum representable integer.", "filename": "/temp/Grandiose-0.sol", "function": "fallback", "lineno": 119, "title": "Integer Overflow ", "type": "Warning"}, {"address": 1599, "code": " commission for all deposits\n\n   ", "debug": "", "description": "Multiple sends exist in one transaction, try to isolate each external call into its own transaction. As external calls can fail accidentally or deliberately.\nConsecutive calls: \nCall at address: 2480\n", "filename": "/temp/Grandiose-0.sol", "function": "fallback", "lineno": 120, "title": "Multiple Calls", "type": "Information"}, {"address": 1791, "code": "      }\n\n            if (user.d", "debug": "", "description": "Multiple sends exist in one transaction, try to isolate each external call into its own transaction. As external calls can fail accidentally or deliberately.\nConsecutive calls: \nCall at address: 2115\nCall at address: 2115\n", "filename": "/temp/Grandiose-0.sol", "function": "fallback", "lineno": 125, "title": "Multiple Calls", "type": "Information"}, {"address": 1791, "code": "      }\n\n            if (user.d", "debug": "", "description": "A possible transaction order independence vulnerability exists in function fallback. The value or direction of the call statement is determined from a tainted storage location", "filename": "/temp/Grandiose-0.sol", "function": "fallback", "lineno": 125, "title": "Transaction order dependence", "type": "Warning"}, {"address": 2480, "code": "    }\n        }\n\n        if (user.de", "debug": "", "description": "A possible transaction order independence vulnerability exists in function fallback. The value or direction of the call statement is determined from a tainted storage location", "filename": "/temp/Grandiose-0.sol", "function": "fallback", "lineno": 135, "title": "Transaction order dependence", "type": "Warning"}, {"address": 3780, "code": "[] _date, address[] _referrer) onlyOwner public {\n        // add initiated investors\n        for (uint i = 0; i < _addr.length; i++) {\n            uint id = addresses.length;\n            if (investors[_addr[i]].deposit == 0) {\n                addresses.push(_addr[i]);\n                depositAmount += _deposit[i];\n            }\n\n            investors[_addr[i]] = Investor(id, _deposit[i], 1, _date[i], _referrer[i]);\n            emit Invest(_addr[i], _deposit  [i], _referrer[i]);\n\n            if (investors[_addr[i]].deposit > gorgonaKiller.deposit) {\n                gorgonaKiller = GorgonaKiller(_addr[i], investors[_addr[i]].deposit);\n            }\n        }\n        lastPaymentDate = now;\n    }\n\n    function() payable public {\n        if (owner == msg.sender) {\n        ", "debug": "calldata_Grandiose_4: 0xfffffffffffffffffffffffffffffffffffffffffffffffffffffffffffffffc\ncalldata_Grandiose_0: 0xa805bfef00000000000000000000000000000000000000000000000000000000\ncalldatasize_Grandiose: 0x4\ncallvalue: 0x0\n", "description": "A possible integer overflow exists in the function `_function_0xa805bfef`.\nThe addition or multiplication may result in a value higher than the maximum representable integer.", "filename": "/temp/Grandiose-0.sol", "function": "_function_0xa805bfef", "lineno": 61, "title": "Integer Overflow ", "type": "Warning"}, {"address": 4780, "code": "int i = addresses.length - ", "debug": "", "description": "Multiple sends exist in one transaction, try to isolate each external call into its own transaction. As external calls can fail accidentally or deliberately.\nConsecutive calls: \nCall at address: 2480\nCall at address: 2115\nCall at address: 2115\nCall at address: 1791\nCall at address: 1599\n", "filename": "/temp/Grandiose-0.sol", "function": "fallback", "lineno": 194, "title": "Multiple Calls", "type": "Information"}, {"address": 5537, "code": ";\n/*\n             ", "debug": "storage_7: 0xffffffffffffffffffffffffffffffffffffffffffffffffffffffffffffffff\ncalldata_Grandiose_4 + calldata_Grandiose_4: 0xffffffffffffffffffffffffffffffffffffffffffffffffffffffffffffffff\nstorage_0: 0x0\ncaller: 0x0\ncalldata_Grandiose_0: 0xa805bfef00000000000000000000000000000000000000000000000000000000\ncalldatasize_Grandiose: 0x4\nstorage_1 +\nkeccac_1461501637330902918203684832716283019655932542975_&\n1461501637330902918203684832716283019655932542975_&\ncalldata_Grandiose_cpy: 0x0\ncallvalue: 0x0\n", "description": "A possible integer overflow exists in the function `_function_0xa805bfef`.\nThe addition or multiplication may result in a value higher than the maximum representable integer.", "filename": "/temp/Grandiose-0.sol", "function": "_function_0xa805bfef", "lineno": 1, "title": "Integer Overflow ", "type": "Warning"}, {"address": 5642, "code": "stor(id, _d", "debug": "The exception is triggered under the following conditions:\n\ncalldata_Grandiose_4 + calldata_Grandiose_4: 0xffffffffffffffffffffffffffffffffffffffffffffffffffffffffffffffff\nstorage_0: 0x0\ncaller: 0x0\ncalldata_Grandiose_0: 0xa805bfef00000000000000000000000000000000000000000000000000000000\ncalldatasize_Grandiose: 0x4\nmem_128 + 32 + 32*calldata_Grandiose_4 + calldata_Grandiose_4: 0x0\nstorage_1 +\nkeccac_1461501637330902918203684832716283019655932542975_&\n1461501637330902918203684832716283019655932542975_&\ncalldata_Grandiose_cpy: 0x0\ncallvalue: 0x0\n", "description": "A reachable exception (opcode 0xfe) has been detected. This can be caused by type errors, division by zero, out-of-bounds array access, or assert violations. This is acceptable in most situations. Note however that `assert()` should only be used to check invariants. Use `require()` for regular input checking. ", "filename": "/temp/Grandiose-0.sol", "function": "_function_0xa805bfef", "lineno": 70, "title": "Exception state", "type": "Informational"}, {"address": 5661, "code": "[_addr[i]] = Investor(id, _d", "debug": "storage_2: 0xa8795cd3fffffffffffffffffffffffffffffffffffffffffffffffffffffffe\nmem_0 + 192 + 32*calldata_Grandiose_4 + calldata_Grandiose_4: 0x57f25cd000000000000000000000000000000000000000000000000000000000\nmem_128 + 32 + 32*calldata_Grandiose_4 + calldata_Grandiose_4: 0xffffffffffffffffffffffffffffffffffffffffffffffffffffffffffffffff\ncalldata_Grandiose_4 + calldata_Grandiose_4: 0xffffffffffffffffffffffffffffffffffffffffffffffffffffffffffffffff\nstorage_0: 0x0\ncaller: 0x0\ncalldata_Grandiose_0: 0xa805bfef00000000000000000000000000000000000000000000000000000000\ncalldatasize_Grandiose: 0x4\nstorage_1 +\nkeccac_1461501637330902918203684832716283019655932542975_&\n1461501637330902918203684832716283019655932542975_&\ncalldata_Grandiose_cpy: 0x0\ncallvalue: 0x0\n", "description": "A possible integer overflow exists in the function `_function_0xa805bfef`.\nThe addition or multiplication may result in a value higher than the maximum representable integer.", "filename": "/temp/Grandiose-0.sol", "function": "_function_0xa805bfef", "lineno": 70, "title": "Integer Overflow ", "type": "Warning"}, {"address": 5700, "code": "r[i], _depo", "debug": "The exception is triggered under the following conditions:\n\nstorage_1 +\nkeccac_1461501637330902918203684832716283019655932542975_&\n1461501637330902918203684832716283019655932542975_&\ncalldata_Grandiose_cpy: 0xffffffffffffffffffffffffffffffffffffffffffffffffffffffffffffffff\ncalldata_Grandiose_4 + calldata_Grandiose_4: 0xffffffffffffffffffffffffffffffffffffffffffffffffffffffffffffffff\nstorage_0: 0x0\ncaller: 0x0\ncalldata_Grandiose_0: 0xa805bfef00000000000000000000000000000000000000000000000000000000\ncalldatasize_Grandiose: 0x4\nmem_128 + 32 + 32*calldata_Grandiose_4 + calldata_Grandiose_4: 0x0\ncallvalue: 0x0\n", "description": "A reachable exception (opcode 0xfe) has been detected. This can be caused by type errors, division by zero, out-of-bounds array access, or assert violations. This is acceptable in most situations. Note however that `assert()` should only be used to check invariants. Use `require()` for regular input checking. ", "filename": "/temp/Grandiose-0.sol", "function": "_function_0xa805bfef", "lineno": 71, "title": "Exception state", "type": "Informational"}, {"address": 5736, "code": "[i], _re", "debug": "The exception is triggered under the following conditions:\n\nmem_128 + 32 + 32*calldata_Grandiose_4 + calldata_Grandiose_4: 0xffffffffffffffffffffffffffffffffffffffffffffffffffffffffffffffff\nstorage_1 +\nkeccac_1461501637330902918203684832716283019655932542975_&\n1461501637330902918203684832716283019655932542975_&\ncalldata_Grandiose_cpy: 0xffffffffffffffffffffffffffffffffffffffffffffffffffffffffffffffff\ncalldata_Grandiose_4 + calldata_Grandiose_4: 0xffffffffffffffffffffffffffffffffffffffffffffffffffffffffffffffff\nstorage_0: 0x0\ncaller: 0x0\ncalldata_Grandiose_0: 0xa805bfef00000000000000000000000000000000000000000000000000000000\ncalldatasize_Grandiose: 0x4\nmem_160 +\n32*calldata_Grandiose_4 + calldata_Grandiose_4 +\n32 +\n32*calldata_Grandiose_4 + calldata_Grandiose_32 + 4: 0x0\ncallvalue: 0x0\n", "description": "A reachable exception (opcode 0xfe) has been detected. This can be caused by type errors, division by zero, out-of-bounds array access, or assert violations. This is acceptable in most situations. Note however that `assert()` should only be used to check invariants. Use `require()` for regular input checking. ", "filename": "/temp/Grandiose-0.sol", "function": "_function_0xa805bfef", "lineno": 71, "title": "Exception state", "type": "Informational"}, {"address": 5765, "code": "rrer[i]);\n\n ", "debug": "The exception is triggered under the following conditions:\n\nmem_160 +\n32*calldata_Grandiose_4 + calldata_Grandiose_4 +\n32 +\n32*calldata_Grandiose_4 + calldata_Grandiose_32 + 4: 0xffffffffffffffffffffffffffffffffffffffffffffffffffffffffffffffff\nmem_128 + 32 + 32*calldata_Grandiose_4 + calldata_Grandiose_4: 0xffffffffffffffffffffffffffffffffffffffffffffffffffffffffffffffff\nstorage_1 +\nkeccac_1461501637330902918203684832716283019655932542975_&\n1461501637330902918203684832716283019655932542975_&\ncalldata_Grandiose_cpy: 0xffffffffffffffffffffffffffffffffffffffffffffffffffffffffffffffff\ncalldata_Grandiose_4 + calldata_Grandiose_4: 0xffffffffffffffffffffffffffffffffffffffffffffffffffffffffffffffff\nstorage_0: 0x0\ncaller: 0x0\ncalldata_Grandiose_0: 0xa805bfef00000000000000000000000000000000000000000000000000000000\ncalldatasize_Grandiose: 0x4\nmem_192 +\n32*calldata_Grandiose_4 + calldata_Grandiose_4 +\n32*calldata_Grandiose_4 + calldata_Grandiose_32 + 4 +\n32 +\n32*calldata_Grandiose_4 + calldata_Grandiose_32 + 36: 0x0\ncallvalue: 0x0\n", "description": "A reachable exception (opcode 0xfe) has been detected. This can be caused by type errors, division by zero, out-of-bounds array access, or assert violations. This is acceptable in most situations. Note however that `assert()` should only be used to check invariants. Use `require()` for regular input checking. ", "filename": "/temp/Grandiose-0.sol", "function": "_function_0xa805bfef", "lineno": 71, "title": "Exception state", "type": "Informational"}, {"address": 6677, "debug": "timestamp: 0x0\nstorage_3 +\nkeccac_1461501637330902918203684832716283019655932542975_&\n1461501637330902918203684832716283019655932542975_&\ncaller: 0x1\nstorage_0 +\nkeccac_1461501637330902918203684832716283019655932542975_&\n1461501637330902918203684832716283019655932542975_&\ncaller: 0xffffffffffffffffffffffffffffffffffffffffffffffffffffffffffffffff\ncaller: 0x0\nstorage_0: 0xffffffffffffffffffffffffffffffffffffffff00\ncalldatasize_Grandiose: 0x3\ncallvalue: 0x0\n", "description": "A possible integer underflow exists in the function `fallback`.\nThe subtraction may result in a value < 0.", "filename": "/temp/Grandiose-0.sol", "function": "fallback", "lineno": 225, "title": "Integer Underflow", "type": "Warning"}, {"address": 6834, "code": "dr].date + 20 hours > now", "debug": "storage_7: 0x0\ncalldata_Grandiose_4: 0x1\nstorage_9: 0x0\ncalldata_Grandiose_0: 0xe115234300000000000000000000000000000000000000000000000000000000\ncalldatasize_Grandiose: 0x4\ncallvalue: 0x0\n", "description": "A possible integer underflow exists in the function `payout(uint256)`.\nThe subtraction may result in a value < 0.", "filename": "/temp/Grandiose-0.sol", "function": "payout(uint256)", "lineno": 156, "title": "Integer Underflow", "type": "Warning"}, {"address": 6835, "code": "dr].date + 20 hours > now) {\n", "debug": "storage_7: 0x0\ncalldata_Grandiose_4: 0x0\nstorage_9: 0x0\ncalldata_Grandiose_0: 0xe115234300000000000000000000000000000000000000000000000000000000\ncalldatasize_Grandiose: 0x4\ncallvalue: 0x0\n", "description": "A possible integer underflow exists in the function `payout(uint256)`.\nThe subtraction may result in a value < 0.", "filename": "/temp/Grandiose-0.sol", "function": "payout(uint256)", "lineno": 156, "title": "Integer Underflow", "type": "Warning"}, {"address": 6874, "code": "sAmount(addr);", "debug": "The exception is triggered under the following conditions:\n\nstorage_7: 0x1\ncalldata_Grandiose_4: 0xffffffffffffffffffffffffffffffffffffffffffffffffffffffffffffffff\nstorage_9: 0x0\ncalldata_Grandiose_0: 0xe115234300000000000000000000000000000000000000000000000000000000\ncalldatasize_Grandiose: 0x4\ncallvalue: 0x0\n", "description": "A reachable exception (opcode 0xfe) has been detected. This can be caused by type errors, division by zero, out-of-bounds array access, or assert violations. This is acceptable in most situations. Note however that `assert()` should only be used to check invariants. Use `require()` for regular input checking. ", "filename": "/temp/Grandiose-0.sol", "function": "payout(uint256)", "lineno": 160, "title": "Exception state", "type": "Informational"}, {"address": 6993, "code": "ors[addr].date = now;\n\n        ", "debug": "storage_3 +\nkeccac_1461501637330902918203684832716283019655932542975_&\n1461501637330902918203684832716283019655932542975_&\n1461501637330902918203684832716283019655932542975_&\nUDiv(storage_75276140696391174450305814049576319106646922510300487059720162673006384432776_+\n115792089237316195423570985008687907853269984665640564039457584007913129639935_+\nstorage_7_+\n115792089237316195423570985008687907853269984665640564039457584007913129639935*\ncalldata_Grandiose_4,\n_____256): 0xfffffffffffffffffffffffffffffffffffffffffffffffffffffffffffef6c0\nstorage_7: 0x200000000000000000000000000000000000000001\ncalldata_Grandiose_4: 0x0\nstorage_9: 0x0\ncalldata_Grandiose_0: 0xe115234300000000000000000000000000000000000000000000000000000000\ncalldatasize_Grandiose: 0x4\ncallvalue: 0x0\n", "description": "A possible integer overflow exists in the function `payout(uint256)`.\nThe addition or multiplication may result in a value higher than the maximum representable integer.", "filename": "/temp/Grandiose-0.sol", "function": "payout(uint256)", "lineno": 161, "title": "Integer Overflow ", "type": "Warning"}, {"address": 7448, "code": "ses;\n    mapping(address =", "debug": "The exception is triggered under the following conditions:\n\ncalldata_Grandiose_4: 0x0\nstorage_7: 0x0\ncalldata_Grandiose_0: 0xedf26d9b00000000000000000000000000000000000000000000000000000000\ncalldatasize_Grandiose: 0x4\ncallvalue: 0x0\n", "description": "A reachable exception (opcode 0xfe) has been detected. This can be caused by type errors, division by zero, out-of-bounds array access, or assert violations. This is acceptable in most situations. Note however that `assert()` should only be used to check invariants. Use `require()` for regular input checking. ", "filename": "/temp/Grandiose-0.sol", "function": "_function_0xedf26d9b", "lineno": 24, "title": "Exception state", "type": "Informational"}, {"address": 7668, "code": "              return", "debug": "storage_7: 0x0\nstorage_9: 0xff00\ncalldata_Grandiose_0: 0xe115234300000000000000000000000000000000000000000000000000000000\ncalldatasize_Grandiose: 0x4\ncallvalue: 0x0\n", "description": "A possible integer underflow exists in the function `payout(uint256)`.\nThe subtraction may result in a value < 0.", "filename": "/temp/Grandiose-0.sol", "function": "payout(uint256)", "lineno": 199, "title": "Integer Underflow", "type": "Warning"}, {"address": 7694, "code": "mit NextRoun", "debug": "The exception is triggered under the following conditions:\n\nstorage_7: 0x0\nstorage_9: 0xff00\ncalldata_Grandiose_0: 0xe115234300000000000000000000000000000000000000000000000000000000\ncalldatasize_Grandiose: 0x4\ncallvalue: 0x0\n", "description": "A reachable exception (opcode 0xfe) has been detected. This can be caused by type errors, division by zero, out-of-bounds array access, or assert violations. This is acceptable in most situations. Note however that `assert()` should only be used to check invariants. Use `require()` for regular input checking. ", "filename": "/temp/Grandiose-0.sol", "function": "payout(uint256)", "lineno": 203, "title": "Exception state", "type": "Informational"}, {"address": 8048, "code": ";\n    }\n\n ", "debug": "storage_3: 0xffffffffffffffffffffffffffffffffffffffffffffffffffffffffffffffff\nstorage_9: 0xff00\ncalldata_Grandiose_0: 0xe115234300000000000000000000000000000000000000000000000000000000\ncalldatasize_Grandiose: 0x4\nstorage_7: 0x1\ncallvalue: 0x0\n", "description": "A possible integer overflow exists in the function `payout(uint256)`.\nThe addition or multiplication may result in a value higher than the maximum representable integer.", "filename": "/temp/Grandiose-0.sol", "function": "payout(uint256)", "lineno": 213, "title": "Integer Overflow ", "type": "Warning"}], "success": true}
