{"error": null, "issues": [{"address": 1460, "code": "  function add(u", "debug": "The exception is triggered under the following conditions:\n\nstorage_2 +\nkeccac_1461501637330902918203684832716283019655932542975_&\n1461501637330902918203684832716283019655932542975_&\n1461501637330902918203684832716283019655932542975_&\ncalldata_Storage_4: 0xffffffffffffffffffffffffffffffffffffffffffffffffffffffffffffffff\ntimestamp: 0xfffffffffffffffffffffffffffffffffffffffffffffffffffffffffffffffe\ncalldata_Storage_0: 0x6f77926b00000000000000000000000000000000000000000000000000000000\ncalldatasize_Storage: 0x4\ncallvalue: 0x0\n", "description": "A reachable exception (opcode 0xfe) has been detected. This can be caused by type errors, division by zero, out-of-bounds array access, or assert violations. This is acceptable in most situations. Note however that `assert()` should only be used to check invariants. Use `require()` for regular input checking. ", "filename": "/temp/Leprechaun-0.sol", "function": "getUser(address)", "lineno": 58, "title": "Exception state", "type": "Informational"}, {"address": 1494, "code": "      r", "debug": "storage_0 +\nkeccac_1461501637330902918203684832716283019655932542975_&\n1461501637330902918203684832716283019655932542975_&\n1461501637330902918203684832716283019655932542975_&\ncalldata_Storage_4: 0x8000000000000000000000000000000000000000000000000000000000000000\ncalldata_Storage_0: 0x6f77926b00000000000000000000000000000000000000000000000000000000\ncalldatasize_Storage: 0x4\nstorage_2 +\nkeccac_1461501637330902918203684832716283019655932542975_&\n1461501637330902918203684832716283019655932542975_&\n1461501637330902918203684832716283019655932542975_&\ncalldata_Storage_4: 0x0\ncallvalue: 0x0\n", "description": "A possible integer overflow exists in the function `getUser(address)`.\nThe addition or multiplication may result in a value higher than the maximum representable integer.", "filename": "/temp/Leprechaun-0.sol", "function": "getUser(address)", "lineno": 44, "title": "Integer Overflow ", "type": "Warning"}, {"address": 1517, "code": "  }\n\n    function di", "debug": "The exception is triggered under the following conditions:\n\nstorage_0 +\nkeccac_1461501637330902918203684832716283019655932542975_&\n1461501637330902918203684832716283019655932542975_&\n1461501637330902918203684832716283019655932542975_&\ncalldata_Storage_4: 0x8000000000000000000000000000000000000000000000000000000000000000\nstorage_2 +\nkeccac_1461501637330902918203684832716283019655932542975_&\n1461501637330902918203684832716283019655932542975_&\n1461501637330902918203684832716283019655932542975_&\ncalldata_Storage_4: 0xffffffffffffffffffffffffffffffffffffffffffffffffffffffffffffffff\ntimestamp: 0xffffffffffffffffffffffffffffffffffffffffffffffffffffffffffffffff\ncalldata_Storage_0: 0x6f77926b00000000000000000000000000000000000000000000000000000000\ncalldatasize_Storage: 0x4\ncallvalue: 0x0\n", "description": "A reachable exception (opcode 0xfe) has been detected. This can be caused by type errors, division by zero, out-of-bounds array access, or assert violations. This is acceptable in most situations. Note however that `assert()` should only be used to check invariants. Use `require()` for regular input checking. ", "filename": "/temp/Leprechaun-0.sol", "function": "getUser(address)", "lineno": 45, "title": "Exception state", "type": "Informational"}], "success": true}
